<?xml version="1.0"?>
<robot name="antenna" xmlns:xacro="http://www.ros.org/wiki/xacro">

  <xacro:property name="pi" value="3.1415926535897931"/>
  <xacro:property name="mass" value="1" />

  <xacro:include filename="$(find antenna_description)/urdf/antenna.gazebo" />

  <link name="world"/>

  <joint name="fixed" type="fixed">
    <parent link="world"/>
    <child link="link1"/>
  </joint>

<!-- LINK 1 -->
  <link name="link1">
    <collision>
      <origin xyz="0 0 0.05" rpy="0 0 0"/>
      <geometry>
      	<box size="0.72 0.72 0.1"/>
      </geometry>
    </collision>

    <visual>
      <origin xyz="0 0 0.05" rpy="0 0 0"/>
      <geometry>
	       <box size="0.72 0.72 0.1"/>
      </geometry>
    </visual>

    <inertial>
      <origin xyz="0 0 0.05" rpy="0 0 0"/>
      <mass value="${mass}"/>
      <inertia
	  ixx="1" ixy="0.0" ixz="0.0"
	  iyy="1" iyz="0.0"
	  izz="1"/>
    </inertial>
  </link>

<!-- LEG JOINT -->
  <joint name="leg_joint" type="continuous">
    <parent link="link1"/>
    <child link="link2"/>
    <origin xyz="0 0 0.5" rpy="0 0 0"/>
    <axis xyz="0 0 1"/>
    <dynamics damping="0.7"/>
  </joint>

<!-- LINK 2 -->
  <link name="link2">
    <collision>
      <origin xyz="0 0 0" rpy="0 0 0"/>
      <geometry>
	<box size="0.1 0.1 0.8"/>
      </geometry>
    </collision>

    <visual>
      <origin xyz="0 0 0" rpy="0 0 0"/>
      <geometry>
	<box size="0.1 0.1 0.8"/>
      </geometry>
    </visual>

    <inertial>
      <origin xyz="0 0 0.4" rpy="0 0 0"/>
      <mass value="${mass * 4.69}"/>
      <inertia
	  ixx="0.25" ixy="0.0" ixz="0.0"
	  iyy="0.25" iyz="0.0"
	  izz="0.006"/>
    </inertial>
  </link>

<!-- DISH JOINT -->
  <joint name="dish_joint" type="revolute">
    <parent link="link2"/>
    <child link="link3"/>
    <origin xyz="0 0 0.45" rpy="0 ${pi / (-2)} 0"/>
    <axis xyz="0 1 0"/>
    <limit effort="30" lower="0" upper="${pi}" velocity="0.02094"/>
    <dynamics damping="0" friction="10"/>
  </joint>

<!-- LINK 3 -->
  <link name="link3">
    <collision>
      <origin xyz="0 0 0" rpy="0 0 0"/>
      <geometry>
	<box size="0.1 0.8 0.2"/>
      </geometry>
    </collision>

    <visual>
      <origin xyz="0 0 0" rpy="0 0 0"/>
      <geometry>
	<box size="0.1 0.8 0.2"/>
      </geometry>
    </visual>

    <inertial>
      <origin xyz="0 0 0.1" rpy="0 0 0"/>
      <mass value="${mass * pi / 2}"/>
      <inertia
	  ixx="0.0884" ixy="0.0" ixz="0.0"
	  iyy="0.0065" iyz="0.0"
	  izz="0.0845"/>
    </inertial>
  </link>

  <joint name="joint3" type="fixed">
    <parent link="link3"/>
    <child link="link4"/>
  </joint>

<!-- LINK 4 -->
  <link name="link4">
    <collision>
      <origin xyz="0 0 0.1" rpy="0 0 0"/>
      <geometry>
        <cylinder length="0.05" radius="0.6"/>
      </geometry>
    </collision>

    <visual>
      <origin xyz="0 0 0.1" rpy="0 0 0"/>
      <geometry>
        <cylinder length="0.05" radius="0.6"/>
      </geometry>
    </visual>

    <inertial>
      <mass value="${mass * 4}" />
      <origin xyz="0 0 0.025" rpy="0 0 0"/>
      <inertia ixx="0.00083" ixy="0" ixz="0" iyy="0.00083" iyz="0" izz="0.00083" />
    </inertial>
  </link>

  <joint name="joint4" type="fixed">
    <parent link="link4"/>
    <child link="link5"/>
  </joint>

<!-- LINK 5 -->
  <link name="link5">
    <collision>
      <origin xyz="0 0 0.25" rpy="0 0 0"/>
      <geometry>
        <cylinder length="0.5" radius="0.03"/>
      </geometry>
    </collision>

    <visual>
      <origin xyz="0 0 0.25" rpy="0 0 0"/>
      <geometry>
        <cylinder length="0.5" radius="0.03"/>
      </geometry>
    </visual>

    <inertial>
      <mass value="${mass * 0.05}" />
      <origin xyz="0 0 0.25" rpy="0 0 0"/>
      <inertia ixx="0.004" ixy="0" ixz="0" iyy="0.004" iyz="0" izz="0.004" />
    </inertial>
  </link>


  <transmission name="tran1">
    <type>transmission_interface/SimpleTransmission</type>
    <joint name="leg_joint">
      <hardwareInterface>hardware_interface/EffortJointInterface</hardwareInterface>
    </joint>
    <actuator name="motor1">
      <hardwareInterface>hardware_interface/EffortJointInterface</hardwareInterface>
      <mechanicalReduction>1</mechanicalReduction>
    </actuator>
  </transmission>

  <transmission name="tran2">
    <type>transmission_interface/SimpleTransmission</type>
    <joint name="dish_joint">
      <hardwareInterface>hardware_interface/EffortJointInterface</hardwareInterface>
    </joint>
    <actuator name="motor2">
      <hardwareInterface>hardware_interface/EffortJointInterface</hardwareInterface>
      <mechanicalReduction>1</mechanicalReduction>
    </actuator>
  </transmission>
</robot>
