<?xml version="1.0" ?>
<robot name="testbot">
	<material name="black">
		<color rgba="0.0 0.0 0.0 1.0"/>
	</material>
	<material name="orange">
		<color rgba="1.0 0.4 0.0 1.0"/>
	</material>
	<link name="world"/>
	<joint name="fixed" type="fixed">
		<parent link="world"/>
		<child link="link1"/>
	</joint>
	<link name="link1" output="screen">
		<collision>
			<origin xyz="0 0 0" rpy="0 0 0"/>
			<geometry>
				<box size="0.72 0.72 0.1"/>
			</geometry>
		</collision>
		<visual>
			<origin xyz="0 0 0" rpy="0 0 0"/>
			<geometry>
				<box size="0.72 0.72 0.1"/>
			</geometry>
			<material name="black"/>
		</visual>
		<inertial>
			<origin xyz="0 0 0.025" rpy="0 0 0"/>
			<mass value="1"/>
			<inertia ixx="1.0" ixy="0.0" ixz="0.0" 
							   iyy="1.0" iyz="0.0" 
							   			 izz="1.0"/>
		</inertial>
	</link>
	<joint name="joint1" type="revolute">
		<parent link="link1"/>
		<child link="link2"/>
		<origin xyz="0 0 0.5" rpy="0 0 0"/>
		<axis xyz="0 0 1"/>
		<limit effort="30" lower="-3.141" upper="3.141" velocity="1.571"/>
		<dynamics damping="0.7"/>
	</joint>
	<link name="link2">
		<collision>
			<origin xyz="0 0 0" rpy="0 0 0"/>
			<geometry>
				<box size="0.1 0.1 0.8"/>
			</geometry>
		</collision>
		<visual>
			<origin xyz="0 0 0" rpy="0 0 0"/>
			<geometry>
				<box size="0.1 0.1 0.8"/>
			</geometry>
			<material name="orange"/>
		</visual>
		<inertial>
			<origin xyz="0 0 0.4" rpy="0 0 0"/>
			<mass value="1"/>
			<inertia ixx="1.0" ixy="0.0" ixz="0.0" iyy="1.0" iyz="0.0" izz="1.0"/>
		</inertial>
	</link>
	<joint name="joint2" type="revolute">
		<parent link="link2"/>
		<child link="link3"/>
		<origin xyz="0 0 0.45" rpy="0 0 0"/>
		<axis xyz="0 1 0"/>
		<limit effort="30" lower="-1.571" upper="1.571" velocity="1.571"/>
		<dynamics damping="0.7"/>
	</joint>
	<link name="link3">
		<collision>
			<origin xyz="0 0 0" rpy="0 0 0"/>
			<geometry>
				<box size="0.1 0.8 0.2"/>
			</geometry>
		</collision>
		<visual>
			<origin xyz="0 0 0" rpy="0 0 0"/>
			<geometry>
				<box size="0.1 0.8 0.2"/>
			</geometry>
			<material name="black"/>
		</visual>
		<inertial>
			<origin xyz="0 0 0.1" rpy="0 0 0"/>
			<mass value="1"/>
			<inertia ixx="1.0" ixy="0.0" ixz="0.0" iyy="1.0" iyz="0.0" izz="1.0"/>
		</inertial>
	</link>
	<joint name="joint3" type="fixed">
		<parent link="link3"/>
		<child link="link4"/>
		<!--<origin xyz="0 0 1.0" rpy="0 0 0"/>-->
		<!--<axis xyz="0 1 0"/>-->
		<!--<limit effort="30" lower="-2.617" upper="2.617" velocity="1.571"/>-->
	</joint>
	<link name="link4">
		<collision>
			<origin xyz="0 0 0.1" rpy="0 0 0"/>
			<geometry>
				<cylinder length="0.05" radius="0.6"/>
			</geometry>
		</collision>
		<visual>
			<origin xyz="0 0 0.1" rpy="0 0 0"/>
			<geometry>
				<cylinder length="0.05" radius="0.6"/>
			</geometry>
			<material name="orange"/>
		</visual>
		<inertial>
			<origin xyz="0 0 0.025" rpy="0 0 0"/>
			<mass value="1"/>
			<inertia ixx="1.0" ixy="0.0" ixz="0.0" iyy="1.0" iyz="0.0" izz="1.0"/>
		</inertial>
	</link>
	<joint name="joint4" type="fixed">
		<parent link="link4"/>
		<child link="link5"/>
	</joint>
	<link name="link5">
		<collision>
			<origin xyz="0 0 0.25" rpy="0 0 0"/>
			<geometry>
				<cylinder length="0.5" radius="0.03"/>
			</geometry>
		</collision>
		<visual>
			<origin xyz="0 0 0.25" rpy="0 0 0"/>
			<geometry>
				<cylinder length="0.5" radius="0.03"/>
			</geometry>
			<material name="black"/>
		</visual>
		<inertial>
			<origin xyz="0 0 0.25" rpy="0 0 0"/>
			<mass value="1"/>
			<inertia ixx="1.0" ixy="0.0" ixz="0.0" iyy="1.0" iyz="0.0" izz="1.0"/>
		</inertial>
	</link>


	<gazebo>
		<plugin name="gazebo_ros_control" filename="libgazebo_ros_control.so">
			<robotNamespace>/antenna</robotNamespace>
		</plugin>
	</gazebo>

	<transmission name="tran1">
	    <type>transmission_interface/SimpleTransmission</type>
	    <joint name="joint1">
		    <hardwareInterface>hardware_interface/EffortJointInterface</hardwareInterface>
	    </joint>
	    <actuator name="motor1">
	      	<hardwareInterface>hardware_interface/EffortJointInterface</hardwareInterface>
	      	<mechanicalReduction>1</mechanicalReduction>
	    </actuator>
	</transmission>

	<transmission name="tran2">
	    <type>transmission_interface/SimpleTransmission</type>
	    <joint name="joint2">
	      	<hardwareInterface>hardware_interface/EffortJointInterface</hardwareInterface>
	    </joint>
	    <actuator name="motor2">
	      	<hardwareInterface>hardware_interface/EffortJointInterface</hardwareInterface>
	      	<mechanicalReduction>1</mechanicalReduction>
	    </actuator>
	</transmission>

	<gazebo reference="link1">
		<material>Gazebo/Black</material>
	</gazebo>
	<gazebo reference="link2">
		<material>Gazebo/Orange</material>
		<mu1>0.2</mu1>
    	<mu2>0.2</mu2>
	</gazebo>
	<gazebo reference="link3">
		<material>Gazebo/Black</material>
		<mu1>0.2</mu1>
    	<mu2>0.2</mu2>
	</gazebo>
	<gazebo reference="link4">
		<material>Gazebo/Orange</material>
	</gazebo>
	<gazebo reference="link5">
		<material>Gazebo/Black</material>
	</gazebo>

</robot>